<?xml version="1.0"?>
<robot name="ugv1" xmlns:xacro="http://ros.org/wiki/xacro">
  <xacro:arg name="namespace" default="ugv1"/>
  <link name="base_link">
    <visual>
      <origin xyz="0 0 0.3" rpy="0 0 0"/>
      <geometry>
        <box size="0.719 0.57861 0.18"/>
      </geometry>
    </visual>
    <collision>
      <origin xyz="0 0 0.3" rpy="0 0 0"/>
      <geometry>
        <box size="0.719 0.57861 0.18"/>
      </geometry>
    </collision>
    <visual>
      <origin xyz="0 0 0.176" rpy="0 0 0"/>
      <geometry>
        <box size="0.524 0.27 0.06495"/>
      </geometry>
    </visual>
    <collision>
      <origin xyz="0 0 0.176" rpy="0 0 0"/>
      <geometry>
        <box size="0.524 0.27 0.06495"/>
      </geometry>
    </collision>
    <visual>
      <origin xyz="0 0 0.046225" rpy="0 0 0"/>
      <geometry>
        <box size="0.69 0.27 0.1945"/>
      </geometry>
    </visual>
    <collision>
      <origin xyz="0 0 0.046225" rpy="0 0 0"/>
      <geometry>
        <box size="0.69 0.27 0.1945"/>
      </geometry>
    </collision>
  </link>
  <link name="Velodyne_VLP_16">
    <visual>
      <origin xyz="0 -0.00165 0" rpy="0 0 0"/>
      <geometry>
        <cylinder radius="0.052" length="0.0727"/>
      </geometry>
    </visual>
    <collision>
      <origin xyz="0 -0.00165 0" rpy="0 0 0"/>
      <geometry>
        <cylinder radius="0.052" length="0.0727"/>
      </geometry>
    </collision>
  </link>
  <joint name="base_link_Velodyne_VLP_16_joint" type="fixed">
    <parent link="base_link"/>
    <child link="Velodyne_VLP_16"/>
    <origin xyz="0 0 0.74062" rpy="0 0 0"/>
  </joint>
  <link name="imu">
  </link>
  <joint name="base_link_imu_joint" type="fixed">
    <parent link="base_link"/>
    <child link="imu"/>
    <origin xyz="0 0 0.39062" rpy="0 0 0"/>
  </joint>
  <link name="gyr">
  </link>
  <joint name="base_link_gyr_joint" type="fixed">
    <parent link="base_link"/>
    <child link="gyr"/>
    <origin xyz="0 0 0.36062" rpy="0 0 0"/>
  </joint>
  <link name="acc">
  </link>
  <joint name="base_link_acc_joint" type="fixed">
    <parent link="base_link"/>
    <child link="acc"/>
    <origin xyz="0 0 0.36062" rpy="0 0 0"/>
  </joint>
  <link name="com">
  </link>
  <joint name="base_link_com_joint" type="fixed">
    <parent link="base_link"/>
    <child link="com"/>
    <origin xyz="0 0 0.38062" rpy="0 0 0"/>
  </joint>
  <link name="Brackets_v2">
  </link>
  <joint name="base_link_Brackets_v2_joint" type="fixed">
    <parent link="base_link"/>
    <child link="Brackets_v2"/>
    <origin xyz="0 0 0.39062" rpy="0 0 0"/>
  </joint>
  <link name="solid">
  </link>
  <joint name="Brackets_v2_solid_joint" type="fixed">
    <parent link="Brackets_v2"/>
    <child link="solid"/>
    <origin xyz="0 0 0" rpy="0 0 0"/>
  </joint>
  <link name="robot_gps">
  </link>
  <joint name="base_link_robot_gps_joint" type="fixed">
    <parent link="base_link"/>
    <child link="robot_gps"/>
    <origin xyz="0 0 0.37062" rpy="0 0 0"/>
  </joint>
  <link name="gps">
  </link>
  <joint name="base_link_gps_joint" type="fixed">
    <parent link="base_link"/>
    <child link="gps"/>
    <origin xyz="-0.365 -0.167 0.302" rpy="0 0 0"/>
  </joint>
  <link name="solid_0">
  </link>
  <joint name="base_link_solid_0_joint" type="fixed">
    <parent link="base_link"/>
    <child link="solid_0"/>
    <origin xyz="0.3585 0 0.29062" rpy="0 0 0"/>
  </joint>
  <link name="depth_camera">
  </link>
  <joint name="solid_0_depth_camera_joint" type="fixed">
    <parent link="solid_0"/>
    <child link="depth_camera"/>
    <origin xyz="0 0 0.015" rpy="0 0 0"/>
  </joint>
  <link name="rgb_camera">
  </link>
  <joint name="solid_0_rgb_camera_joint" type="fixed">
    <parent link="solid_0"/>
    <child link="rgb_camera"/>
    <origin xyz="0 0 0.015" rpy="-1.570796 0 -1.570796"/>
  </joint>
  <link name="front_rgbd_camera_link">
    <visual>
      <origin xyz="-0.02 0 0.015" rpy="0 0 0"/>
      <geometry>
        <box size="0.04 0.165 0.03"/>
      </geometry>
    </visual>
    <collision>
      <origin xyz="-0.02 0 0.015" rpy="0 0 0"/>
      <geometry>
        <box size="0.04 0.165 0.03"/>
      </geometry>
    </collision>
  </link>
  <joint name="solid_0_front_rgbd_camera_link_joint" type="fixed">
    <parent link="solid_0"/>
    <child link="front_rgbd_camera_link"/>
    <origin xyz="0.007 0 0" rpy="0 0 0"/>
  </joint>
  <link name="compass">
  </link>
  <joint name="base_link_compass_joint" type="fixed">
    <parent link="base_link"/>
    <child link="compass"/>
    <origin xyz="0.127 -0.129 0.212" rpy="0 0 0"/>
  </joint>
  <link name="gyro">
  </link>
  <joint name="base_link_gyro_joint" type="fixed">
    <parent link="base_link"/>
    <child link="gyro"/>
    <origin xyz="0.127 -0.129 0.212" rpy="0 0 0"/>
  </joint>
  <link name="accelerometer">
  </link>
  <joint name="base_link_accelerometer_joint" type="fixed">
    <parent link="base_link"/>
    <child link="accelerometer"/>
    <origin xyz="0.127 -0.129 0.212" rpy="0 0 0"/>
  </joint>
  <link name="base_docking_contact">
  </link>
  <joint name="base_link_base_docking_contact_joint" type="fixed">
    <parent link="base_link"/>
    <child link="base_docking_contact"/>
    <origin xyz="0.35 0 0.09" rpy="0 0 0"/>
  </joint>
  <joint name="back_right_wheel_joint" type="continuous">
    <parent link="base_link"/>
    <child link="back_right_wheel_link"/>
    <axis xyz="0 -0.000004 -1"/>
    <limit effort="100" velocity="100"/>
    <origin xyz="-0.2225 -0.2045 0" rpy="1.5708 -0.00041 0"/>
  </joint>
  <link name="back_right_wheel_link">
  </link>
  <joint name="back_left_wheel_joint" type="continuous">
    <parent link="base_link"/>
    <child link="back_left_wheel_link"/>
    <axis xyz="0 -0.000004 -1"/>
    <limit effort="100" velocity="100"/>
    <origin xyz="-0.222501 0.20764 0" rpy="1.5708 -0.00041 0"/>
  </joint>
  <link name="back_left_wheel_link">
  </link>
  <joint name="front_left_wheel_joint" type="continuous">
    <parent link="base_link"/>
    <child link="front_left_wheel_link"/>
    <axis xyz="0 -0.000004 -1"/>
    <limit effort="100" velocity="100"/>
    <origin xyz="0.222499 0.207638 0" rpy="1.5708 -0.000205 0"/>
  </joint>
  <link name="front_left_wheel_link">
  </link>
  <joint name="front_right_wheel_joint" type="continuous">
    <parent link="base_link"/>
    <child link="front_right_wheel_link"/>
    <axis xyz="0 -0.000004 -1"/>
    <limit effort="100" velocity="100"/>
    <origin xyz="0.222499 -0.201316 0" rpy="1.5708 -0.000205 0"/>
  </joint>
  <link name="front_right_wheel_link">
  </link>
  <link name="base_logo_rear">
  </link>
  <joint name="base_link_base_logo_rear_joint" type="fixed">
    <parent link="base_link"/>
    <child link="base_logo_rear"/>
    <origin xyz="-0.345001 0.003186 0" rpy="0 0 1.570796"/>
  </joint>
  <link name="base_logo_front">
  </link>
  <joint name="base_link_base_logo_front_joint" type="fixed">
    <parent link="base_link"/>
    <child link="base_logo_front"/>
    <origin xyz="0.345 0 0" rpy="0 0 -1.570796"/>
  </joint>
  <link name="base_logo_right">
  </link>
  <joint name="base_link_base_logo_right_joint" type="fixed">
    <parent link="base_link"/>
    <child link="base_logo_right"/>
    <origin xyz="0 -0.28931 0.29062" rpy="0 0 -3.141592"/>
  </joint>
  <link name="base_logo_left">
  </link>
  <joint name="base_link_base_logo_left_joint" type="fixed">
    <parent link="base_link"/>
    <child link="base_logo_left"/>
    <origin xyz="0 0.28931 0.29062" rpy="0 0 0"/>
  </joint>
  <link name="base_chapa_front">
  </link>
  <joint name="base_link_base_chapa_front_joint" type="fixed">
    <parent link="base_link"/>
    <child link="base_chapa_front"/>
    <origin xyz="0.359 0 0.30062" rpy="0 0 0"/>
  </joint>
  <link name="base_chapa">
  </link>
  <joint name="base_link_base_chapa_joint" type="fixed">
    <parent link="base_link"/>
    <child link="base_chapa"/>
    <origin xyz="0 0 0.39062" rpy="0 0 0"/>
  </joint>
  <webots>
    <plugin type="simulator.robot_driver.main">
      <namespace>$(arg namespace)</namespace>
    </plugin>
  </webots>
</robot>
